Workbook
Name 年龄段下拉: #REF!
Name 年龄段下拉: #REF!
Name 其他分组下拉: #REF!
Name 其他分组下拉: #REF!
Name 项目名称: #REF!
Name 项目名称: #REF!
Name 年龄段下拉: #REF!
Name 其他分组下拉: #REF!
Name 项目名称: #REF!
Name 年龄段下拉: #REF!
Name 其他分组下拉: #REF!
Name 项目名称: #REF!
Name 年龄段下拉: #REF!
Name 其他分组下拉: #REF!
Name 项目名称: #REF!

Sheet 主封面
C2: 标题 | D2: 生化免疫组定性项目性能验证报告
C3: 文件编号 | D3: BG-SM-CZ-040 | G3: 版本号 | H3: 01
C4: 颁布部门 | D4: 生化免疫组 | E4: 生效日期 | F4: 2025.04.01 | G4: 修改号 | H4: 0
C5: 编制人 | D5: 金子铮 | E5: 审核人 | F5: 杨静 | G5: 批准人 | H5: 王学晶
A7: 民航总医院检验科
A11: 性能验证报告
D20: 项目名称： | E20: 乙肝表面抗原（HBsAg）
D22: 试剂厂家： | E22: 罗氏
D24: 仪器名称： | E24: 全自动电化学发光免疫分析仪
D26: 仪器厂家： | E26: 罗氏
D28: 仪器型号： | E28: e601
D30: 仪器编号： | E30: MHZYY-JYK-SM-1016
D32: 操作人员： | E32: 金子铮
D34: 审核人员： | E34: 杨静
D36: 验证日期： | E36: 2025年05月12日-2025年05月16日

Sheet 结果汇总
A1: 验证结论汇总
A2: 一、验证项目及系统信息
A3: 项目名称 | B3: =主封面!E20 -> 乙肝表面抗原（HBsAg） | E3: 仪器型号 | G3: =主封面!E28 -> e601
A4: 项目方法 | B4: 电化学发光法 | E4: 仪器编号 | G4: =主封面!E30 -> MHZYY-JYK-SM-1016
A5: 报告单位 | B5: COI
A6: 试剂 | B6: 罗氏乙肝表面抗原测定试剂盒 | E6: 试剂批号 | G6: 812808
A7: 校准品 | B7: 罗氏试剂盒自带校准品 | E7: 校准品批号 | G7: 812808
A8: 质控品 | B8: 康彻斯坦 | E8: 质控品批号 | G8: 202505006
A9: 操作人员 | B9: =[1]主封面!E32 -> 金子铮 | E9: 审核人员 | G9: =[1]主封面!E34 -> 杨静
A10: 验证日期 | B10: =主封面!E36 -> 2025年05月12日-2025年05月16日
A12: 二、验证内容
A13: 精密度、方法符合率、检出限。
A15: 三、验证结论
A16: 验证内容 | B16: 验证要求 | F16: 验证结果 | H16: 验证结论
A17: 精密度 | B17: 批内CV ≤7.5% | F17: ="低值"&TEXT(精密度!D30,"0.00%")&" 高值"&TEXT(精密度!D31,"0.00%") -> 低值7.24% 高值3.28% | H17: =[1]精密度!A34 -> 符合要求
B18: 实验室内CV ≤10.0% | F18: ="低值"&TEXT(精密度!G30,"0.00%")&" 高值"&TEXT(精密度!G31,"0.00%") -> 低值6.72% 高值2.95%
A19: 方法符合率 | B19: 阳性符合率≥95% | F19: =方法符合率!C40 -> 1 | H19: ='[1]正确度-偏倚评估'!A32 -> 符合要求
B20: 阴性符合率≥95% | F20: =方法符合率!G40 -> 1
A21: 方法检出限 | B21: 检出限浓度的样品阳性率≥95% | F21: 0.38U/mL 阳性率 100% | H21: 符合要求
A23: 四、评价结论
A24: 本实验室在罗氏e601上对乙肝表面抗原的分析性能，包括精密度、方法符合率和方法检出限均符合要求。

Sheet 精密度
A1: 精密度验证报告
A3: 一、验证方案: CNAS-GL038:2019《临床免疫学定性检验程序性能验证指南》6.2； WS/T 492-2016《临床检验定量测定项目精密度与正确度性能验证》3.1-3.3； WS/T 408-2024《定量检验程序分析性能验证指南》5。
A4: 选取至少两个浓度的质控品，包括阴性和弱阳性。每天检测1批，每批检测2个水平，每个水平重复检测3次，连续检测5天，计算批内和实验室内总CV和SD，与实验室规定标准进行比较，同时使用统计学检验将估算值与标准进行比较。
A9: 二、要求
A10: 批内和实验室内变异系数或标准差≤实验室规定标准，则精密度验证通过；若大于规定标准，进行统计学检验，判断精密度是否可接受。 实验室规定标准：参考WS/T403-2024《临床化学检验常用项目分析质量标准》附录A不精密度要求，或卫健委临检中心推荐的允许总误差相关要求（即批内≤1/4TEA、实验内CV≤1/3TEA）。无上述相关要求的，结合试剂厂家的精密度数据进行判断。
A12: 三、实验基本参数
A13: 项目名称 | C13: =结果汇总!B3 -> 乙肝表面抗原（HBsAg） | G13: 仪器型号 | I13: =结果汇总!G3 -> e601
A14: 项目方法 | C14: =IF([1]结果汇总!$B$4="","",[1]结果汇总!$B$4) -> 化学发光法 | G14: 仪器编号 | I14: =[1]主封面!E30 -> MHZYY-JYK-SM-1006
A15: 精密度验证物质 | C15: 质控品（2水平） | G15: 单位 | I15: =结果汇总!B5 -> COI
A16: 质控品来源 | C16: =结果汇总!B8 -> 康彻斯坦 | G16: 质控品批号 | I16: =结果汇总!G8 -> 202505006
A17: 试剂 | C17: =结果汇总!B6 -> 罗氏乙肝表面抗原测定试剂盒 | G17: 试剂批号 | I17: =结果汇总!G6 -> 812808
A18: 校准品 | C18: =结果汇总!B7 -> 罗氏试剂盒自带校准品 | G18: 校准品批号 | I18: =结果汇总!G7 -> 812808
A19: 允许总误差(TEA) | C19: 行标与临检中心无相应要求 | G19: 操作人员 | I19: =[1]主封面!E32 -> 金子铮
A20: 批内CV数据 | C20: ≤ | D20: 0.075 | G20: 审核人员 | I20: =[1]主封面!E34 -> 杨静
A21: 实验室内CV数据 | C21: ≤ | D21: 0.1 | G21: 验证完成日期 | I21: 45793
A24: 四、实验结果与数据处理
A25: 见下页
A27: 五、实验结论
A29: 精密度验证物质 | C29: 均值 | D29: 批内 变异系数CV% | E29: 批间 变异系数CV% | G29: 实验室内 变异系数 CV% | I29: 是否满足判定标准 | K29: 批内精密度 验证结果 | L29: 实验室内 精密度 验证结果
A30: 低值质控品 | C30: =E58 -> 0.48013333 | D30: =E59 -> 0.072380848 | E30: =C57/E58 -> 0.032077129 | G30: =E61 -> 0.067242846 | I30: =IF(AND(D30<=D20,E30<=D21),"是","否") -> 是 | K30: =IF(E59<L65,"符合要求","不符合要求") -> 符合要求 | L30: =IF(E61<L69,"符合要求","不符合要求") -> 符合要求
A31: 高值质控品 | C31: =K58 -> 4.1306667 | D31: =K59 -> 0.032755519 | E31: =C92/K58 -> 0.012506768 | G31: =K61 -> 0.029524599 | I31: =IF(AND(D31<=D20,E31<=D21),"是","否") -> 是 | K31: =IF(K59<L96,"符合要求","不符合要求") -> 符合要求 | L31: =IF(K61<L99,"符合要求","不符合要求") -> 符合要求
A32: 乙肝表面抗原精密度验证：
A34: 符合要求
A37: 精密度验证
B38: 分析仪器 | C38: =I13 -> e601 | F38: 浓度水平数 | G38: 2 | H38: 实验室规定的精密度要求（SD/CV%）
B39: 分析物 | C39: =C13 -> 乙肝表面抗原（HBsAg） | F39: 单位 | G39: =I15 -> COI | H39: 批内 | I39: CV | J39: =D20 -> 0.075 | K39: SD | L39: =E58*J39 -> 0.03601
B40: 验证样本 | C40: 质控品 | H40: 实验室内 | I40: CV | J40: =D21 -> 0.1 | K40: SD | L40: =E58*J40 -> 0.048013333
B41: 计划运行天数 | C41: 5 | E41: 计划重复次数 | G41: 3
C42: 水平1 | H42: 水平2
B43: 日期 | C43: 第1次 | D43: 第2次 | E43: 第3次 | H43: 第1次 | I43: 第2次 | K43: 第3次
A44: 第1天 | B44: 2025.5.12 | C44: 0.464 | D44: 0.466 | E44: 0.535 | H44: 3.97 | I44: 4.02 | K44: 4.18 | M44: =IF(COUNT(C44:E44)=0,"",COUNT(C44:E44)) -> 3 | N44: =IF(M44<>"",AVERAGE(C44:E44),"") -> 0.48833333 | O44: =IF(N44<>"",STDEV(C44:E44),"") -> 0.040426889 | P44: =IF(O44<>"",O44^2,"") -> 0.0016343333
A45: 第2天 | B45: 2025.5.13 | C45: 0.466 | D45: 0.446 | E45: 0.476 | H45: 4.4 | I45: 4.02 | K45: 4.09 | M45: =IF(COUNT(C45:E45)=0,"",COUNT(C45:E45)) -> 3 | N45: =IF(M45<>"",AVERAGE(C45:E45),"") -> 0.46266667 | O45: =IF(N45<>"",STDEV(C45:E45),"") -> 0.015275252 | P45: =IF(O45<>"",O45^2,"") -> 0.00023333333
A46: 第3天 | B46: 2025.5.14 | C46: 0.53 | D46: 0.468 | E46: 0.423 | H46: 4.09 | I46: 4.12 | K46: 4.08 | M46: =IF(COUNT(C46:E46)=0,"",COUNT(C46:E46)) -> 3 | N46: =IF(M46<>"",AVERAGE(C46:E46),"") -> 0.47366667 | O46: =IF(N46<>"",STDEV(C46:E46),"") -> 0.053724606 | P46: =IF(O46<>"",O46^2,"") -> 0.0028863333
A47: 第4天 | B47: 2025.5.15 | C47: 0.434 | D47: 0.494 | E47: 0.493 | H47: 4.11 | I47: 4.16 | K47: 4.2 | M47: =IF(COUNT(C47:E47)=0,"",COUNT(C47:E47)) -> 3 | N47: =IF(M47<>"",AVERAGE(C47:E47),"") -> 0.47366667 | O47: =IF(N47<>"",STDEV(C47:E47),"") -> 0.03435598 | P47: =IF(O47<>"",O47^2,"") -> 0.0011803333
A48: 第5天 | B48: 2025.5.16 | C48: 0.514 | D48: 0.495 | E48: 0.498 | H48: 4.36 | I48: 4.18 | K48: 3.98 | M48: =IF(COUNT(C48:E48)=0,"",COUNT(C48:E48)) -> 3 | N48: =IF(M48<>"",AVERAGE(C48:E48),"") -> 0.50233333 | O48: =IF(N48<>"",STDEV(C48:E48),"") -> 0.010214369 | P48: =IF(O48<>"",O48^2,"") -> 0.00010433333
C54: =IF(COUNT(C44:C53)=0,"",COUNT(C44:C53)) -> 5 | D54: =IF(COUNT(D44:D53)=0,"",COUNT(D44:D53)) -> 5 | E54: =IF(COUNT(E44:E53)=0,"",COUNT(E44:E53)) -> 5 | F54: =IF(COUNT(F44:F53)=0,"",COUNT(F44:F53)) | G54: =IF(COUNT(G44:G53)=0,"",COUNT(G44:G53)) | H54: =IF(COUNT(H49:H53)=0,"",COUNT(H49:H53)) | I54: =IF(COUNT(I49:I53)=0,"",COUNT(I49:I53)) | J54: =IF(COUNT(J49:J53)=0,"",COUNT(J49:J53)) | K54: =IF(COUNT(K49:K53)=0,"",COUNT(K49:K53)) | L54: =IF(COUNT(L49:L53)=0,"",COUNT(L49:L53))
B55: 重复天数D | C55: =C41 -> 5 | G55: 重复次数n | H55: =G41 -> 3 | O55: =(H55-1)/C55 -> 0.4 | P55: =O55*H56*H56 -> 5.8344792e-07
B56: 批间方差（Vb） | C56: =C57^2 -> 0.0002372 | G56: 批内方差（Vr） | H56: =AVERAGE(P44:P53) -> 0.0012077333 | K56: 总方差（VT） | L56: =((H55-1)/H55)*H56+C56 -> 0.0010423556 | O56: =H56*(H55-1) -> 0.0024154667
B57: 批间标准差（Sb） | C57: =STDEV(N44:N48) -> 0.015401299 | G57: 批内标准差（Sr） | H57: =SQRT(H56) -> 0.034752458 | K57: 实验室内标准差（Sl） | L57: =SQRT(L56) -> 0.032285532 | P57: =H55*C56 -> 0.0007116
D58: 总均值 | E58: =AVERAGE(N44:N53) -> 0.48013333 | J58: 总均值 | K58: =AVERAGE(N79:N88) -> 4.1306667
...

Sheet 方法符合率
A1: 方法符合率验证报告
A2: 一、验证方案： CNAS-GL038:2019《临床免疫学定性检验程序性能验证指南》6.1.2。
A3: 选取已知结果的室间质评样本或厂家参考品，至少10份阴性样本和至少10份阳性样本（阳性样本要包含2-4 倍 cut-off 值之间的弱阳性样本和极高值阳性样本），按照公式计算阴性符合率和阳性符合率：阳性符合率=[真阳性/（真阳性+假阴性）] × 100%，阴性符合率=[真阴性/（真阴性+假阳性）] × 100%，总符合率=[(真阳性+真阴性)/总样本数] × 100%计算。
A5: 二、要求
A6: 实验室规定标准：阴性符合率、阳性符合率均≥95%。
A8: 三、实验基本参数
A9: 项目名称 | C9: =结果汇总!B3 -> 乙肝表面抗原（HBsAg） | E9: 仪器型号 | G9: =结果汇总!G3 -> e601
A10: 项目方法 | C10: =结果汇总!B4 -> 电化学发光法 | E10: 仪器编号 | G10: =结果汇总!G4 -> MHZYY-JYK-SM-1016
A11: 单位 | C11: =结果汇总!B5 -> COI
A12: 试剂 | C12: =结果汇总!B6 -> 罗氏乙肝表面抗原测定试剂盒 | E12: 试剂批号 | G12: =结果汇总!G6 -> 812808
A13: 校准品 | C13: =结果汇总!B7 -> 罗氏试剂盒自带校准品 | E13: 校准品批号 | G13: =结果汇总!G7 -> 812808
A14: 符合率验证物质 | C14: 室间质评样本 | E14: 操作人员 | G14: =主封面!E32 -> 金子铮
A15: 阳性符合率 | C15: ≥ | D15: 0.95 | E15: 审核人员 | G15: =主封面!E34 -> 杨静
A16: 阴性符合率 | C16: ≥ | D16: 0.95 | E16: 验证完成日期 | G16: =精密度!I21 -> 45793
A18: 四、实验数据及处理结果
A19: HBsAg | B19: 室间质评样品 | F19: 待评价方法结果
A20: 1 | B20: N1 | D20: N | F20: 0.526 | H20: N
A21: 2 | B21: N2 | D21: N | F21: 0.425 | H21: N
A22: 3 | B22: N3 | D22: N | F22: 0.611 | H22: N
A23: 4 | B23: N4 | D23: N | F23: 0.458 | H23: N
A24: 5 | B24: N5 | D24: N | F24: 0.518 | H24: N
A25: 6 | B25: N6 | D25: N | F25: 0.567 | H25: N
A26: 7 | B26: N7 | D26: N | F26: 0.449 | H26: N
A27: 8 | B27: N8 | D27: N | F27: 0.634 | H27: N
A28: 9 | B28: N9 | D28: N | F28: 0.637 | H28: N
A29: 10 | B29: N10 | D29: N | F29: 0.358 | H29: N
A30: 11 | B30: P1 | D30: P | F30: 2.36 | H30: P
A31: 12 | B31: P2 | D31: P | F31: 12.99 | H31: P
... A39: 20 | B39: P10 | D39: P | F39: 6.36 | H39: P
A40: 阳性符合率 | C40: 1 | E40: 阴性符合率 | G40: 1
A41: 总符合率 | C41: 1
A43: 五、实验结论
A45: 乙肝表面抗原方法符合率验证：
A46: 符合要求

Sheet 方法检出限（合适时）
A1: 方法检出限验证报告
A2: 一、验证方案： CNAS-GL038:2019《临床免疫学定性检验程序性能验证指南》6.1.2。
A3: 使用定值标准物质的样品质如国际参考品、国家参考品、厂商参考品。使用定值标准物质的样本梯度稀释至厂商声明的检出限浓度，样本总数不得少于 20个。稀释液可根据情况选用厂商提供的稀释液或阴性血清，该阴性血清除被验证的目标物必须阴性外，其对应的相关物质（如抗原或抗体）也必须阴性，且试剂说明书上申明的干扰物质必须在允许范围之内。
A5: 二、要求
A6: 实验室规定标准：≥95%的样本检出阳性
A8: 三、实验基本参数
A9: 项目名称 | C9: =结果汇总!B3 -> 乙肝表面抗原（HBsAg） | E9: 仪器型号 | G9: =结果汇总!G3 -> e601
A10: 项目方法 | C10: =结果汇总!B4 -> 电化学发光法 | E10: 仪器编号 | G10: =结果汇总!G4 -> MHZYY-JYK-SM-1016
A11: 单位 | C11: =结果汇总!B5 -> COI
A12: 试剂 | C12: =结果汇总!B6 -> 罗氏乙肝表面抗原测定试剂盒 | E12: 试剂批号 | G12: =结果汇总!G6 -> 812808
A13: 校准品 | C13: =结果汇总!B7 -> 罗氏试剂盒自带校准品 | E13: 校准品批号 | G13: =结果汇总!G7 -> 812808
A14: 检出限验证物质 | C14: 厂商参考品 | E14: 操作人员 | G14: =主封面!E32 -> 金子铮
A15: 声明检出限 | C15: 0.04U/mL | E15: 审核人员 | G15: =主封面!E34 -> 杨静
A16: 验证完成日期
A18: 四、实验数据及处理结果
A19: HBsAg | B19: 参考品原浓度 | D19: 参考品稀释后浓度 | F19: 待评价方法结果
A20: 1 | B20: 0.5U/mL | D20: 0.38U/mL | F20: 1.16 | H20: P
A21: 2 | F21: 1.13 | H21: P
A22: 3 | F22: 1.2 | H22: P
A23: 4 | F23: 1.15 | H23: P
A24: 5 | F24: 1.28 | H24: P
A25: 6 | F25: 1.25 | H25: P
A26: 7 | F26: 1.18 | H26: P
A27: 8 | F27: 1.19 | H27: P
A28: 9 | F28: 1.25 | H28: P
A29: 10 | F29: 1.24 | H29: P
A30: 11 | F30: 1.21 | H30: P
A31: 12 | F31: 1.08 | H31: P
A32: 13 | F32: 1.11 | H32: P
... A39: 20 | F39: 1.15 | H39: P
A40: 阳性样本 | C40: 1
A42: 五、实验结论
A44: 乙肝表面抗原方法检出限验证：
A45: 符合要求

Sheet 分析特异性（合适时）
A1: 分析特异性验证报告
A2: 一、验证方案： CNAS-GL037:2019《临床化学定量检验程序性能验证指南》6.4； WS/T 416-2013《干扰试验指南》。
A3: 选取1个基础样本，考虑参考医学决定水平或参考区间限值，或参考《干扰实验指南》附录B中建议的实验浓度。干扰物原液中的浓度应高于厂家声明20倍，按照干扰物低浓度样本（基础样本950ul+溶剂（生理盐水等）50ul）、干扰物高浓度样本样本（基础样本950ul+干扰物原液50ul）配制，将二者按不同比例混合，配置5个干扰物水平的样本。重复检测3次，记录数据，计算相对偏倚。
A5: 二、要求
A6: 加入干扰物后相对偏倚≤允许偏倚，认为此干扰物浓度无明显干扰。 允许偏倚标准：参考WS/T403-2024《临床化学检验常用项目分析质量标准》附录A允许偏倚的要求，或卫健委临检中心推荐的允许总误差相关要求（即相对偏倚≤1/2TEA）。
A8: 三、实验基本参数
A9: 项目名称 | C9: =[1]结果汇总!B3 -> 降钙素（CT） | E9: 仪器型号 | G9: =[1]结果汇总!G3 -> DXI800急诊
A10: 项目方法 | C10: =[1]结果汇总!B4 -> 化学发光法 | E10: 仪器编号 | G10: =[1]结果汇总!G4 -> MHZYY-JYK-SM-1006
A11: 单位 | C11: =[1]结果汇总!B5 -> ng/L | E11: 样本来源 | G11: 临床标本
A12: 试剂 | C12: =[1]结果汇总!B6 -> 沃文特降钙素测定试剂盒 | E12: 试剂批号 | G12: =[1]结果汇总!G6 -> 407421
A13: 校准品 | C13: =[1]结果汇总!B7 -> 沃文特试剂盒自带校准品 | E13: 校准品批号 | G13: =[1]结果汇总!G7 -> 407421
A14: 试剂厂商声明的分析特异性： | E14: 胆红素 | F14: ≤ | G14: 684 | H14: umol/L
E15: 甘油三酯 | F15: ≤ | G15: 11.3 | H15: mmol/L
A16: 允许总误差(TEA) | C16: =IF([1]结果汇总!$G$5="","",[1]结果汇总!$G$5) -> 0.3 | E16: 血红蛋白 | F16: ≤ | G16: 5 | H16: g/dL
A17: 允许偏倚 | C17: =C16/2 -> 0.15 | E17: 操作人员 | G17: =[1]主封面!E32 -> 金子铮
A18: 验证完成日期 | C18: ='[1]正确度-偏倚评估'!C21 -> 45426 | E18: 审核人员 | G18: =[1]主封面!E34 -> 杨静
A20: 四、实验数据及处理结果
A21: 见下页
A22: 五、实验结论
A24: 干扰物质 | B24: 胆红素 | D24: 甘油三酯 | F24: 血红蛋白
A25: 抗干扰浓度 | B25: 700umol/L | D25: 9.3mmol/L | F25: 6g/L
A26: 降钙素（CT）分析特异性验证：
A27: 降钙素（CT）对胆红素、甘油三酯、血红蛋白的抗干扰能力符合要求。
A28: 胆红素≤700umol/L，甘油三酯≤9.3mmol/L，血红蛋白≤6g/L无明显干扰。
A31: 分析仪器 | B31: 贝克曼DXI800 | D31: 临床样本 | E31: 1 | F31: 实验室规定的精密度要求（SD/CV%）
A32: 分析物 | B32: =C9 -> 降钙素（CT） | D32: 系列样品 | E32: 6 | G32: 批内CV | H32: =C16/4 -> 0.075
A33: 单位 | B33: =C11 -> ng/L | D33: 需验证的干扰物数量 | E33: 3 | G33: 实验室内CV | H33: =C16/3 -> 0.1
A34: TEA | B34: =C16 -> 0.3 | D34: 计划重复次数 | E34: 3 | G34: 允许偏倚 | H34: =C17 -> 0.15
A36: 1.干扰物高浓度与低浓度样本制备
A37: 样本号 | B37: 基础样品用量 | D37: 干扰物原液用量 | F37: 溶剂用量
A38: 干扰物低浓度样本 | B38: 950ul | D38: 0 | F38: 50ul
A39: 干扰物高浓度样本 | B39: 950ul | D39: 50ul | F39: 0
A41: 本底浓度检测 | C41: 胆红素 | D41: 甘油三酯 | E41: 血红蛋白
A42: 干扰物低浓度样本 | C42: 10 | D42: 1.3 | E42: 0
A44: 2.干扰物不同浓度系列样品制备
A45: 系列样品号 | B45: 干扰物高浓度 样本用量mL | D45: 干扰物低浓度 样本用量mL | F45: 胆红素浓度 | G45: 甘油三酯浓度 | H45: 血红蛋白浓度
A46: 1 | B46: 0 | D46: 1 | F46: =C42 -> 10 | G46: =D42 -> 1.3 | H46: =E42 -> 0
A47: 2 | B47: 0.25 | D47: 0.75 | F47: =$F$50*B47+$F$46*D47 -> 182.5 | G47: =$G$50*B47+$G$46*D47 -> 3.975 | H47: =$H$50*B47+$H$46*D47 -> 2
A48: 3 | B48: 0.5 | D48: 0.5 | F48: =$F$50*B48+$F$46*D48 -> 355 | G48: =$G$50*B48+$G$46*D48 -> 6.65 | H48: =$H$50*B48+$H$46*D48 -> 4
A49: 4 | B49: 0.75 | D49: 0.25 | F49: =$F$50*B49+$F$46*D49 -> 527.5 | G49: =$G$50*B49+$G$46*D49 -> 9.325 | H49: =$H$50*B49+$H$46*D49 -> 6
...

Sheet 原始数据
A1: 定性项目性能验证原始结果记录表
A3: 项目名称 | D3: 报告单位
A4: 试剂品牌 | D4: 项目方法
A5: 仪器型号 | D5: 仪器编号
A6: 检出限 | D6: 验证日期
A8: 类别 | B8: 名称 | D8: 品牌 | E8: 批号 | F8: 失效日期
A9: 试剂
A10: 校准品
A11: 质控品
A13: 操作者 | D13: 审核者
A15: 质控 | B15: 水平1 | C15: 水平2
A16: 靶值
A17: 检测结果
A19: 一、精密度验证
A20: 水平1 | B20: 第1次 | C20: 第2次 | D20: 第3次 | F20: 精密度验证物质：
A21: 第1天
A22: 第2天
A23: 第3天
A24: 第4天
A25: 第5天
A27: 水平2 | B27: 第1次 | C27: 第2次 | D27: 第3次
A28: 第1天
A29: 第2天
A30: 第3天
A31: 第4天
A32: 第5天
A34: 二、方法符合率验证
B35: 室间质评样品 | D35: 待评价方法结果
A36: 1
A37: 2
A38: 3
A39: 4
A40: 5
A41: 6
A42: 7
A43: 8
A44: 9
A45: 10
A46: 11
A47: 12
...
